2025-09-27 23:28:55,579 - WARNING: 尝试 1/3 失败: Cmd('git') failed due to: exit code(1)
  cmdline: git push --porcelain -- origin --set-upstream main
  stderr: 'error: src refspec --set-upstream does not match any
error: failed to push some refs to 'git@github.com''
2025-09-27 23:28:57,813 - WARNING: 尝试 2/3 失败: Cmd('git') failed due to: exit code(1)
  cmdline: git push --porcelain -- origin --set-upstream main
  stderr: 'error: src refspec --set-upstream does not match any
error: failed to push some refs to 'git@github.com''
2025-09-27 23:29:37,716 - WARNING: 尝试 1/3 失败: Cmd('git') failed due to: exit code(1)
  cmdline: git push --porcelain -- origin --set-upstream main
  stderr: 'error: src refspec --set-upstream does not match any
error: failed to push some refs to 'git@github.com''
2025-09-27 23:29:39,973 - WARNING: 尝试 2/3 失败: Cmd('git') failed due to: exit code(1)
  cmdline: git push --porcelain -- origin --set-upstream main
  stderr: 'error: src refspec --set-upstream does not match any
error: failed to push some refs to 'git@github.com''
2025-09-27 23:30:25,334 - WARNING: 尝试 1/3 失败: Cmd('git') failed due to: exit code(1)
  cmdline: git push --porcelain -- origin --set-upstream main
  stderr: 'error: src refspec --set-upstream does not match any
error: failed to push some refs to 'git@github.com''
2025-09-27 23:30:27,574 - WARNING: 尝试 2/3 失败: Cmd('git') failed due to: exit code(1)
  cmdline: git push --porcelain -- origin --set-upstream main
  stderr: 'error: src refspec --set-upstream does not match any
error: failed to push some refs to 'git@github.com''
2025-09-27 23:30:31,816 - WARNING: 尝试 3/3 失败: Cmd('git') failed due to: exit code(1)
  cmdline: git push --porcelain -- origin --set-upstream main
  stderr: 'error: src refspec --set-upstream does not match any
error: failed to push some refs to 'git@github.com''
2025-09-27 23:30:31,816 - ERROR: 同步最终失败
2025-09-27 23:30:31,817 - ERROR: 错误详情
Traceback (most recent call last):
  File "C:\Users\10129\CodeBuddy\MutilTask\github_sync.py", line 82, in <module>
    syncer.sync()
    ~~~~~~~~~~~^^
  File "C:\Users\10129\CodeBuddy\MutilTask\github_sync.py", line 68, in sync
    repo.remotes.origin.push(push_args)
    ~~~~~~~~~~~~~~~~~~~~~~~~^^^^^^^^^^^
  File "C:\Python313\Lib\site-packages\git\remote.py", line 1210, in push
    return self._get_push_info(proc, progress, kill_after_timeout=kill_after_timeout)
           ~~~~~~~~~~~~~~~~~~~^^^^^^^^^^^^^^^^^^^^^^^^^^^^^^^^^^^^^^^^^^^^^^^^^^^^^^^
  File "C:\Python313\Lib\site-packages\git\remote.py", line 975, in _get_push_info
    proc.wait(stderr=stderr_text)
    ~~~~~~~~~^^^^^^^^^^^^^^^^^^^^
  File "C:\Python313\Lib\site-packages\git\cmd.py", line 419, in wait
    raise GitCommandError(remove_password_if_present(self.args), status, errstr)
git.exc.GitCommandError: Cmd('git') failed due to: exit code(1)
  cmdline: git push --porcelain -- origin --set-upstream main
  stderr: 'error: src refspec --set-upstream does not match any
error: failed to push some refs to 'git@github.com''
2025-09-27 23:30:40,079 - WARNING: 尝试 1/3 失败: Cmd('git') failed due to: exit code(1)
  cmdline: git push --porcelain -- origin --set-upstream main
  stderr: 'error: src refspec --set-upstream does not match any
error: failed to push some refs to 'git@github.com''
2025-09-27 23:30:42,324 - WARNING: 尝试 2/3 失败: Cmd('git') failed due to: exit code(1)
  cmdline: git push --porcelain -- origin --set-upstream main
  stderr: 'error: src refspec --set-upstream does not match any
error: failed to push some refs to 'git@github.com''
2025-09-27 23:30:46,565 - WARNING: 尝试 3/3 失败: Cmd('git') failed due to: exit code(1)
  cmdline: git push --porcelain -- origin --set-upstream main
  stderr: 'error: src refspec --set-upstream does not match any
error: failed to push some refs to 'git@github.com''
2025-09-27 23:30:46,565 - ERROR: 同步最终失败
2025-09-27 23:30:46,565 - ERROR: 错误详情
Traceback (most recent call last):
  File "C:\Users\10129\CodeBuddy\MutilTask\github_sync.py", line 82, in <module>
    syncer.sync()
    ~~~~~~~~~~~^^
  File "C:\Users\10129\CodeBuddy\MutilTask\github_sync.py", line 68, in sync
    repo.remotes.origin.push(push_args)
    ~~~~~~~~~~~~~~~~~~~~~~~~^^^^^^^^^^^
  File "C:\Python313\Lib\site-packages\git\remote.py", line 1210, in push
    return self._get_push_info(proc, progress, kill_after_timeout=kill_after_timeout)
           ~~~~~~~~~~~~~~~~~~~^^^^^^^^^^^^^^^^^^^^^^^^^^^^^^^^^^^^^^^^^^^^^^^^^^^^^^^
  File "C:\Python313\Lib\site-packages\git\remote.py", line 975, in _get_push_info
    proc.wait(stderr=stderr_text)
    ~~~~~~~~~^^^^^^^^^^^^^^^^^^^^
  File "C:\Python313\Lib\site-packages\git\cmd.py", line 419, in wait
    raise GitCommandError(remove_password_if_present(self.args), status, errstr)
git.exc.GitCommandError: Cmd('git') failed due to: exit code(1)
  cmdline: git push --porcelain -- origin --set-upstream main
  stderr: 'error: src refspec --set-upstream does not match any
error: failed to push some refs to 'git@github.com''
2025-09-27 23:32:24,753 - WARNING: 尝试 1/3 失败: Cmd('git') failed due to: exit code(128)
  cmdline: git push --set-upstream origin main
  stderr: 'fatal: 'git@github.com' does not appear to be a git repository
fatal: Could not read from remote repository.

Please make sure you have the correct access rights
and the repository exists.'
2025-09-27 23:32:27,017 - WARNING: 尝试 2/3 失败: Cmd('git') failed due to: exit code(128)
  cmdline: git push --set-upstream origin main
  stderr: 'fatal: 'git@github.com' does not appear to be a git repository
fatal: Could not read from remote repository.

Please make sure you have the correct access rights
and the repository exists.'
2025-09-27 23:32:31,289 - WARNING: 尝试 3/3 失败: Cmd('git') failed due to: exit code(128)
  cmdline: git push --set-upstream origin main
  stderr: 'fatal: 'git@github.com' does not appear to be a git repository
fatal: Could not read from remote repository.

Please make sure you have the correct access rights
and the repository exists.'
2025-09-27 23:32:31,289 - ERROR: 同步最终失败
2025-09-27 23:32:31,289 - ERROR: 错误详情
Traceback (most recent call last):
  File "C:\Users\10129\CodeBuddy\MutilTask\github_sync.py", line 87, in <module>
    syncer.sync()
    ~~~~~~~~~~~^^
  File "C:\Users\10129\CodeBuddy\MutilTask\github_sync.py", line 70, in sync
    repo.git.push('origin', branch_name, set_upstream=True)
    ~~~~~~~~~~~~~^^^^^^^^^^^^^^^^^^^^^^^^^^^^^^^^^^^^^^^^^^
  File "C:\Python313\Lib\site-packages\git\cmd.py", line 1003, in <lambda>
    return lambda *args, **kwargs: self._call_process(name, *args, **kwargs)
                                   ~~~~~~~~~~~~~~~~~~^^^^^^^^^^^^^^^^^^^^^^^
  File "C:\Python313\Lib\site-packages\git\cmd.py", line 1616, in _call_process
    return self.execute(call, **exec_kwargs)
           ~~~~~~~~~~~~^^^^^^^^^^^^^^^^^^^^^
  File "C:\Python313\Lib\site-packages\git\cmd.py", line 1406, in execute
    raise GitCommandError(redacted_command, status, stderr_value, stdout_value)
git.exc.GitCommandError: Cmd('git') failed due to: exit code(128)
  cmdline: git push --set-upstream origin main
  stderr: 'fatal: 'git@github.com' does not appear to be a git repository
fatal: Could not read from remote repository.

Please make sure you have the correct access rights
and the repository exists.'
2025-09-27 23:35:09,393 - INFO: Git仓库初始化成功
2025-09-27 23:35:09,393 - INFO: 配置的远程仓库URL: git@github.com:ssLinChen/lite-mutil-task-manager.git
2025-09-27 23:35:09,393 - INFO: 测试SSH连接到: github.com
2025-09-27 23:35:12,850 - INFO: SSH连接测试成功: github.com
2025-09-27 23:35:12,851 - INFO: 检查仓库是否存在: ssLinChen/lite-mutil-task-manager 在 github.com
2025-09-27 23:35:24,073 - WARNING: 检查仓库存在性异常: Command '['git', 'ls-remote', 'git@github.com:ssLinChen/lite-mutil-task-manager.git', 'HEAD']' timed out after 10 seconds
2025-09-27 23:35:24,073 - WARNING: 远程仓库不存在或无法访问
2025-09-27 23:35:24,073 - INFO: 请确认仓库URL是否正确，并且您有权限访问该仓库
2025-09-27 23:35:24,078 - INFO: Git身份设置为: tutu <y80200156@mail.ecust.edu.cn>
2025-09-27 23:35:24,128 - INFO: 已添加所有更改到暂存区
2025-09-27 23:35:24,239 - INFO: 已提交更改: Auto-commit at 2025-09-27 23:35:24
2025-09-27 23:35:24,240 - INFO: 更新远程仓库URL: git@github.com -> git@github.com:ssLinChen/lite-mutil-task-manager.git
2025-09-27 23:35:24,269 - INFO: 使用分支: main
2025-09-27 23:35:24,306 - INFO: 本地分支 main 已存在
2025-09-27 23:35:24,306 - INFO: 开始推送到远程仓库...
2025-09-27 23:35:24,306 - INFO: 使用 --set-upstream 选项推送分支 main
2025-09-27 23:35:29,660 - WARNING: 尝试 1/3 失败: Cmd('git') failed due to: exit code(1)
  cmdline: git push --set-upstream origin main
  stderr: 'To github.com:ssLinChen/lite-mutil-task-manager.git
 ! [rejected]        main -> main (fetch first)
error: failed to push some refs to 'github.com:ssLinChen/lite-mutil-task-manager.git'
hint: Updates were rejected because the remote contains work that you do not
hint: have locally. This is usually caused by another repository pushing to
hint: the same ref. If you want to integrate the remote changes, use
hint: 'git pull' before pushing again.
hint: See the 'Note about fast-forwards' in 'git push --help' for details.'
2025-09-27 23:35:29,660 - INFO: 等待 2 秒后重试...
2025-09-27 23:35:31,668 - INFO: Git身份设置为: tutu <y80200156@mail.ecust.edu.cn>
2025-09-27 23:35:31,719 - INFO: 已添加所有更改到暂存区
2025-09-27 23:35:31,786 - INFO: 已提交更改: Auto-commit at 2025-09-27 23:35:31
2025-09-27 23:35:31,787 - INFO: 远程仓库URL已正确设置: git@github.com:ssLinChen/lite-mutil-task-manager.git
2025-09-27 23:35:31,787 - INFO: 使用分支: main
2025-09-27 23:35:31,813 - INFO: 本地分支 main 已存在
2025-09-27 23:35:31,814 - INFO: 开始推送到远程仓库...
2025-09-27 23:35:31,814 - INFO: 使用 --set-upstream 选项推送分支 main
2025-09-27 23:35:35,530 - WARNING: 尝试 2/3 失败: Cmd('git') failed due to: exit code(1)
  cmdline: git push --set-upstream origin main
  stderr: 'To github.com:ssLinChen/lite-mutil-task-manager.git
 ! [rejected]        main -> main (fetch first)
error: failed to push some refs to 'github.com:ssLinChen/lite-mutil-task-manager.git'
hint: Updates were rejected because the remote contains work that you do not
hint: have locally. This is usually caused by another repository pushing to
hint: the same ref. If you want to integrate the remote changes, use
hint: 'git pull' before pushing again.
hint: See the 'Note about fast-forwards' in 'git push --help' for details.'
2025-09-27 23:35:35,530 - INFO: 等待 4 秒后重试...
2025-09-27 23:35:39,536 - INFO: Git身份设置为: tutu <y80200156@mail.ecust.edu.cn>
2025-09-27 23:35:39,587 - INFO: 已添加所有更改到暂存区
2025-09-27 23:35:39,660 - INFO: 已提交更改: Auto-commit at 2025-09-27 23:35:39
2025-09-27 23:35:39,660 - INFO: 远程仓库URL已正确设置: git@github.com:ssLinChen/lite-mutil-task-manager.git
2025-09-27 23:35:39,661 - INFO: 使用分支: main
2025-09-27 23:35:39,689 - INFO: 本地分支 main 已存在
2025-09-27 23:35:39,689 - INFO: 开始推送到远程仓库...
2025-09-27 23:35:39,690 - INFO: 使用 --set-upstream 选项推送分支 main
2025-09-27 23:35:43,479 - WARNING: 尝试 3/3 失败: Cmd('git') failed due to: exit code(1)
  cmdline: git push --set-upstream origin main
  stderr: 'To github.com:ssLinChen/lite-mutil-task-manager.git
 ! [rejected]        main -> main (fetch first)
error: failed to push some refs to 'github.com:ssLinChen/lite-mutil-task-manager.git'
hint: Updates were rejected because the remote contains work that you do not
hint: have locally. This is usually caused by another repository pushing to
hint: the same ref. If you want to integrate the remote changes, use
hint: 'git pull' before pushing again.
hint: See the 'Note about fast-forwards' in 'git push --help' for details.'
2025-09-27 23:35:43,479 - ERROR: 达到最大重试次数，同步最终失败
2025-09-27 23:35:43,480 - ERROR: 错误详情
Traceback (most recent call last):
  File "C:\Users\10129\CodeBuddy\MutilTask\github_sync.py", line 225, in <module>
    syncer.sync()
    ~~~~~~~~~~~^^
  File "C:\Users\10129\CodeBuddy\MutilTask\github_sync.py", line 191, in sync
    self.repo.git.push('origin', branch_name, set_upstream=True)
    ~~~~~~~~~~~~~~~~~~^^^^^^^^^^^^^^^^^^^^^^^^^^^^^^^^^^^^^^^^^^
  File "C:\Python313\Lib\site-packages\git\cmd.py", line 1003, in <lambda>
    return lambda *args, **kwargs: self._call_process(name, *args, **kwargs)
                                   ~~~~~~~~~~~~~~~~~~^^^^^^^^^^^^^^^^^^^^^^^
  File "C:\Python313\Lib\site-packages\git\cmd.py", line 1616, in _call_process
    return self.execute(call, **exec_kwargs)
           ~~~~~~~~~~~~^^^^^^^^^^^^^^^^^^^^^
  File "C:\Python313\Lib\site-packages\git\cmd.py", line 1406, in execute
    raise GitCommandError(redacted_command, status, stderr_value, stdout_value)
git.exc.GitCommandError: Cmd('git') failed due to: exit code(1)
  cmdline: git push --set-upstream origin main
  stderr: 'To github.com:ssLinChen/lite-mutil-task-manager.git
 ! [rejected]        main -> main (fetch first)
error: failed to push some refs to 'github.com:ssLinChen/lite-mutil-task-manager.git'
hint: Updates were rejected because the remote contains work that you do not
hint: have locally. This is usually caused by another repository pushing to
hint: the same ref. If you want to integrate the remote changes, use
hint: 'git pull' before pushing again.
hint: See the 'Note about fast-forwards' in 'git push --help' for details.'
2025-09-27 23:37:40,420 - INFO: Git仓库初始化成功
2025-09-27 23:37:40,420 - INFO: 配置的远程仓库URL: git@github.com:ssLinChen/lite-mutil-task-manager.git
2025-09-27 23:37:40,420 - INFO: 测试SSH连接到: github.com
2025-09-27 23:37:43,922 - INFO: SSH连接测试成功: github.com
2025-09-27 23:37:43,922 - INFO: 检查仓库是否存在: ssLinChen/lite-mutil-task-manager 在 github.com
2025-09-27 23:37:56,769 - WARNING: 检查仓库存在性异常: Command '['git', 'ls-remote', 'git@github.com:ssLinChen/lite-mutil-task-manager.git', 'HEAD']' timed out after 10 seconds
2025-09-27 23:37:56,769 - WARNING: 远程仓库不存在或无法访问
2025-09-27 23:37:56,769 - INFO: 请确认仓库URL是否正确，并且您有权限访问该仓库
2025-09-27 23:37:56,774 - INFO: Git身份设置为: tutu <y80200156@mail.ecust.edu.cn>
2025-09-27 23:37:56,804 - INFO: 已添加所有更改到暂存区
2025-09-27 23:37:56,909 - INFO: 已提交更改: Auto-commit at 2025-09-27 23:37:56
2025-09-27 23:37:56,910 - INFO: 远程仓库URL已正确设置: git@github.com:ssLinChen/lite-mutil-task-manager.git
2025-09-27 23:37:56,910 - INFO: 使用分支: main
2025-09-27 23:37:56,937 - INFO: 本地分支 main 已存在
2025-09-27 23:37:56,937 - INFO: 拉取远程仓库更改...
2025-09-27 23:38:00,749 - INFO: 远程分支 main 存在，执行拉取操作
2025-09-27 23:38:06,092 - WARNING: 检测到不相关的历史记录，尝试使用 --allow-unrelated-histories 选项
2025-09-27 23:38:10,044 - WARNING: 拉取远程更改时出错: Cmd('git') failed due to: exit code(1)
  cmdline: git pull origin main --allow-unrelated-histories
  stdout: 'Auto-merging README.md
CONFLICT (add/add): Merge conflict in README.md
Automatic merge failed; fix conflicts and then commit the result.'
  stderr: 'From github.com:ssLinChen/lite-mutil-task-manager
 * branch            main       -> FETCH_HEAD'
2025-09-27 23:38:10,044 - WARNING: 将尝试强制推送
2025-09-27 23:38:10,044 - INFO: 开始推送到远程仓库...
2025-09-27 23:38:10,044 - WARNING: 使用强制推送选项
2025-09-27 23:38:14,833 - INFO: 同步成功完成
2025-09-27 23:43:49,841 - INFO: Git仓库初始化成功
2025-09-27 23:43:49,842 - INFO: 配置的远程仓库URL: git@github.com:ssLinChen/lite-mutil-task-manager.git
2025-09-27 23:43:49,842 - INFO: 测试SSH连接到: github.com
2025-09-27 23:43:53,301 - INFO: SSH连接测试成功: github.com
2025-09-27 23:43:53,301 - INFO: 检查仓库是否存在: ssLinChen/lite-mutil-task-manager 在 github.com
2025-09-27 23:44:06,342 - WARNING: 检查仓库存在性异常: Command '['git', 'ls-remote', 'git@github.com:ssLinChen/lite-mutil-task-manager.git', 'HEAD']' timed out after 10 seconds
2025-09-27 23:44:06,343 - WARNING: 远程仓库不存在或无法访问
2025-09-27 23:44:06,344 - INFO: 请确认仓库URL是否正确，并且您有权限访问该仓库
2025-09-27 23:44:06,350 - INFO: Git身份设置为: tutu <y80200156@mail.ecust.edu.cn>
2025-09-27 23:44:06,381 - INFO: 已添加所有更改到暂存区
2025-09-27 23:44:06,485 - INFO: 已提交更改: Auto-commit at 2025-09-27 23:44:06
2025-09-27 23:44:06,486 - INFO: 远程仓库URL已正确设置: git@github.com:ssLinChen/lite-mutil-task-manager.git
2025-09-27 23:44:06,487 - INFO: 使用分支: main
2025-09-27 23:44:06,514 - INFO: 本地分支 main 已存在
2025-09-27 23:44:06,514 - INFO: 拉取远程仓库更改...
2025-09-27 23:44:21,456 - INFO: 远程分支 main 存在，执行拉取操作
2025-09-27 23:44:21,494 - WARNING: 拉取远程更改时出错: Cmd('git') failed due to: exit code(128)
  cmdline: git pull origin main --no-rebase
  stderr: 'error: You have not concluded your merge (MERGE_HEAD exists).
hint: Please, commit your changes before merging.
fatal: Exiting because of unfinished merge.'
2025-09-27 23:44:21,494 - WARNING: 将尝试强制推送
2025-09-27 23:44:21,494 - INFO: 开始推送到远程仓库...
2025-09-27 23:44:21,495 - WARNING: 使用强制推送选项
2025-09-27 23:44:29,865 - INFO: 同步成功完成
2025-09-28 01:41:29,967 - ERROR: 配置加载失败: [Errno 2] No such file or directory: 'git_config.json'
2025-09-28 01:43:11,118 - ERROR: 配置加载失败: [Errno 2] No such file or directory: 'git_config.json'
2025-09-28 01:43:34,534 - ERROR: 配置加载失败: [Errno 2] No such file or directory: 'git_config.json'
2025-09-28 01:45:54,926 - INFO: Git仓库初始化成功
2025-09-28 01:45:54,926 - INFO: 配置的远程仓库URL: git@github.com:ssLinChen/lite-mutil-task-manager.git
2025-09-28 01:45:54,926 - INFO: 测试SSH连接到: github.com
2025-09-28 01:45:58,672 - INFO: SSH连接测试成功: github.com
2025-09-28 01:45:58,672 - INFO: 检查仓库是否存在: ssLinChen/lite-mutil-task-manager 在 github.com
2025-09-28 01:46:09,737 - WARNING: 检查仓库存在性异常: Command '['git', 'ls-remote', 'git@github.com:ssLinChen/lite-mutil-task-manager.git', 'HEAD']' timed out after 10 seconds
2025-09-28 01:46:09,738 - WARNING: 远程仓库不存在或无法访问
2025-09-28 01:46:09,738 - INFO: 请确认仓库URL是否正确，并且您有权限访问该仓库
2025-09-28 01:46:09,743 - INFO: Git身份设置为: tutu <y80200156@mail.ecust.edu.cn>
2025-09-28 01:46:09,950 - INFO: 已添加所有更改到暂存区
2025-09-28 01:46:10,205 - INFO: 已提交更改: Auto-commit at 2025-09-28 01:46:10
2025-09-28 01:46:10,207 - INFO: 远程仓库URL已正确设置: git@github.com:ssLinChen/lite-mutil-task-manager.git
2025-09-28 01:46:10,207 - INFO: 使用分支: main
2025-09-28 01:46:10,256 - INFO: 本地分支 main 已存在
2025-09-28 01:46:10,256 - INFO: 拉取远程仓库更改...
2025-09-28 01:46:15,329 - INFO: 远程分支 main 存在，执行拉取操作
2025-09-28 01:46:15,365 - WARNING: 拉取远程更改时出错: Cmd('git') failed due to: exit code(128)
  cmdline: git pull origin main --no-rebase
  stderr: 'error: You have not concluded your merge (MERGE_HEAD exists).
hint: Please, commit your changes before merging.
fatal: Exiting because of unfinished merge.'
2025-09-28 01:46:15,365 - WARNING: 尝试 1/3 失败: Cmd('git') failed due to: exit code(128)
  cmdline: git pull origin main --no-rebase
  stderr: 'error: You have not concluded your merge (MERGE_HEAD exists).
hint: Please, commit your changes before merging.
fatal: Exiting because of unfinished merge.'
2025-09-28 01:46:15,365 - INFO: 等待 2 秒后重试...
2025-09-28 01:46:17,372 - INFO: Git身份设置为: tutu <y80200156@mail.ecust.edu.cn>
2025-09-28 01:46:17,445 - INFO: 已添加所有更改到暂存区
2025-09-28 01:46:17,529 - INFO: 已提交更改: Auto-commit at 2025-09-28 01:46:17
2025-09-28 01:46:17,530 - INFO: 远程仓库URL已正确设置: git@github.com:ssLinChen/lite-mutil-task-manager.git
2025-09-28 01:46:17,531 - INFO: 使用分支: main
2025-09-28 01:46:17,570 - INFO: 本地分支 main 已存在
2025-09-28 01:46:17,570 - INFO: 拉取远程仓库更改...
2025-09-28 01:46:21,623 - INFO: 远程分支 main 存在，执行拉取操作
2025-09-28 01:46:21,657 - WARNING: 拉取远程更改时出错: Cmd('git') failed due to: exit code(128)
  cmdline: git pull origin main --no-rebase
  stderr: 'error: You have not concluded your merge (MERGE_HEAD exists).
hint: Please, commit your changes before merging.
fatal: Exiting because of unfinished merge.'
2025-09-28 01:46:21,657 - WARNING: 尝试 2/3 失败: Cmd('git') failed due to: exit code(128)
  cmdline: git pull origin main --no-rebase
  stderr: 'error: You have not concluded your merge (MERGE_HEAD exists).
hint: Please, commit your changes before merging.
fatal: Exiting because of unfinished merge.'
2025-09-28 01:46:21,657 - INFO: 等待 4 秒后重试...
2025-09-28 01:46:25,662 - INFO: Git身份设置为: tutu <y80200156@mail.ecust.edu.cn>
2025-09-28 01:46:25,742 - INFO: 已添加所有更改到暂存区
2025-09-28 01:46:25,826 - INFO: 已提交更改: Auto-commit at 2025-09-28 01:46:25
2025-09-28 01:46:25,827 - INFO: 远程仓库URL已正确设置: git@github.com:ssLinChen/lite-mutil-task-manager.git
2025-09-28 01:46:25,827 - INFO: 使用分支: main
2025-09-28 01:46:25,869 - INFO: 本地分支 main 已存在
2025-09-28 01:46:25,869 - INFO: 拉取远程仓库更改...
2025-09-28 01:46:30,541 - INFO: 远程分支 main 存在，执行拉取操作
2025-09-28 01:46:30,572 - WARNING: 拉取远程更改时出错: Cmd('git') failed due to: exit code(128)
  cmdline: git pull origin main --no-rebase
  stderr: 'error: You have not concluded your merge (MERGE_HEAD exists).
hint: Please, commit your changes before merging.
fatal: Exiting because of unfinished merge.'
2025-09-28 01:46:30,572 - WARNING: 尝试 3/3 失败: Cmd('git') failed due to: exit code(128)
  cmdline: git pull origin main --no-rebase
  stderr: 'error: You have not concluded your merge (MERGE_HEAD exists).
hint: Please, commit your changes before merging.
fatal: Exiting because of unfinished merge.'
2025-09-28 01:46:30,572 - ERROR: 达到最大重试次数，同步最终失败
2025-09-28 01:46:30,573 - ERROR: 错误详情
Traceback (most recent call last):
  File "C:\Users\10129\CodeBuddy\lite-mutil-task-manager\utils\github_sync.py", line 273, in <module>
    syncer.sync()
    ~~~~~~~~~~~^^
  File "C:\Users\10129\CodeBuddy\lite-mutil-task-manager\utils\github_sync.py", line 197, in sync
    self.repo.git.pull('origin', branch_name, '--no-rebase')
    ~~~~~~~~~~~~~~~~~~^^^^^^^^^^^^^^^^^^^^^^^^^^^^^^^^^^^^^^
  File "C:\Python313\Lib\site-packages\git\cmd.py", line 1003, in <lambda>
    return lambda *args, **kwargs: self._call_process(name, *args, **kwargs)
                                   ~~~~~~~~~~~~~~~~~~^^^^^^^^^^^^^^^^^^^^^^^
  File "C:\Python313\Lib\site-packages\git\cmd.py", line 1616, in _call_process
    return self.execute(call, **exec_kwargs)
           ~~~~~~~~~~~~^^^^^^^^^^^^^^^^^^^^^
  File "C:\Python313\Lib\site-packages\git\cmd.py", line 1406, in execute
    raise GitCommandError(redacted_command, status, stderr_value, stdout_value)
git.exc.GitCommandError: Cmd('git') failed due to: exit code(128)
  cmdline: git pull origin main --no-rebase
  stderr: 'error: You have not concluded your merge (MERGE_HEAD exists).
hint: Please, commit your changes before merging.
fatal: Exiting because of unfinished merge.'
2025-09-28 01:47:36,245 - INFO: Git仓库初始化成功
2025-09-28 01:47:36,246 - INFO: 配置的远程仓库URL: git@github.com:ssLinChen/lite-mutil-task-manager.git
2025-09-28 01:47:36,246 - INFO: 测试SSH连接到: github.com
2025-09-28 01:47:39,281 - INFO: SSH连接测试成功: github.com
2025-09-28 01:47:39,281 - INFO: 检查仓库是否存在: ssLinChen/lite-mutil-task-manager 在 github.com
2025-09-28 01:47:50,494 - WARNING: 检查仓库存在性异常: Command '['git', 'ls-remote', 'git@github.com:ssLinChen/lite-mutil-task-manager.git', 'HEAD']' timed out after 10 seconds
2025-09-28 01:47:50,495 - WARNING: 远程仓库不存在或无法访问
2025-09-28 01:47:50,495 - INFO: 请确认仓库URL是否正确，并且您有权限访问该仓库
2025-09-28 01:47:50,500 - INFO: Git身份设置为: tutu <y80200156@mail.ecust.edu.cn>
2025-09-28 01:47:50,560 - INFO: 已添加所有更改到暂存区
2025-09-28 01:47:50,672 - INFO: 已提交更改: Auto-commit at 2025-09-28 01:47:50
2025-09-28 01:47:50,673 - INFO: 远程仓库URL已正确设置: git@github.com:ssLinChen/lite-mutil-task-manager.git
2025-09-28 01:47:50,674 - INFO: 使用分支: main
2025-09-28 01:47:50,706 - INFO: 本地分支 main 已存在
2025-09-28 01:47:50,706 - INFO: 拉取远程仓库更改...
2025-09-28 01:47:56,365 - INFO: 远程分支 main 存在，执行拉取操作
2025-09-28 01:48:00,276 - INFO: 成功拉取远程更改
2025-09-28 01:48:00,276 - INFO: 开始推送到远程仓库...
2025-09-28 01:48:00,276 - INFO: 使用 --set-upstream 选项推送分支 main
2025-09-28 01:48:05,708 - INFO: 同步成功完成
