2025-09-27 23:28:55,579 - WARNING: 尝试 1/3 失败: Cmd('git') failed due to: exit code(1)
  cmdline: git push --porcelain -- origin --set-upstream main
  stderr: 'error: src refspec --set-upstream does not match any
error: failed to push some refs to 'git@github.com''
2025-09-27 23:28:57,813 - WARNING: 尝试 2/3 失败: Cmd('git') failed due to: exit code(1)
  cmdline: git push --porcelain -- origin --set-upstream main
  stderr: 'error: src refspec --set-upstream does not match any
error: failed to push some refs to 'git@github.com''
2025-09-27 23:29:37,716 - WARNING: 尝试 1/3 失败: Cmd('git') failed due to: exit code(1)
  cmdline: git push --porcelain -- origin --set-upstream main
  stderr: 'error: src refspec --set-upstream does not match any
error: failed to push some refs to 'git@github.com''
2025-09-27 23:29:39,973 - WARNING: 尝试 2/3 失败: Cmd('git') failed due to: exit code(1)
  cmdline: git push --porcelain -- origin --set-upstream main
  stderr: 'error: src refspec --set-upstream does not match any
error: failed to push some refs to 'git@github.com''
2025-09-27 23:30:25,334 - WARNING: 尝试 1/3 失败: Cmd('git') failed due to: exit code(1)
  cmdline: git push --porcelain -- origin --set-upstream main
  stderr: 'error: src refspec --set-upstream does not match any
error: failed to push some refs to 'git@github.com''
2025-09-27 23:30:27,574 - WARNING: 尝试 2/3 失败: Cmd('git') failed due to: exit code(1)
  cmdline: git push --porcelain -- origin --set-upstream main
  stderr: 'error: src refspec --set-upstream does not match any
error: failed to push some refs to 'git@github.com''
2025-09-27 23:30:31,816 - WARNING: 尝试 3/3 失败: Cmd('git') failed due to: exit code(1)
  cmdline: git push --porcelain -- origin --set-upstream main
  stderr: 'error: src refspec --set-upstream does not match any
error: failed to push some refs to 'git@github.com''
2025-09-27 23:30:31,816 - ERROR: 同步最终失败
2025-09-27 23:30:31,817 - ERROR: 错误详情
Traceback (most recent call last):
  File "C:\Users\10129\CodeBuddy\MutilTask\github_sync.py", line 82, in <module>
    syncer.sync()
    ~~~~~~~~~~~^^
  File "C:\Users\10129\CodeBuddy\MutilTask\github_sync.py", line 68, in sync
    repo.remotes.origin.push(push_args)
    ~~~~~~~~~~~~~~~~~~~~~~~~^^^^^^^^^^^
  File "C:\Python313\Lib\site-packages\git\remote.py", line 1210, in push
    return self._get_push_info(proc, progress, kill_after_timeout=kill_after_timeout)
           ~~~~~~~~~~~~~~~~~~~^^^^^^^^^^^^^^^^^^^^^^^^^^^^^^^^^^^^^^^^^^^^^^^^^^^^^^^
  File "C:\Python313\Lib\site-packages\git\remote.py", line 975, in _get_push_info
    proc.wait(stderr=stderr_text)
    ~~~~~~~~~^^^^^^^^^^^^^^^^^^^^
  File "C:\Python313\Lib\site-packages\git\cmd.py", line 419, in wait
    raise GitCommandError(remove_password_if_present(self.args), status, errstr)
git.exc.GitCommandError: Cmd('git') failed due to: exit code(1)
  cmdline: git push --porcelain -- origin --set-upstream main
  stderr: 'error: src refspec --set-upstream does not match any
error: failed to push some refs to 'git@github.com''
2025-09-27 23:30:40,079 - WARNING: 尝试 1/3 失败: Cmd('git') failed due to: exit code(1)
  cmdline: git push --porcelain -- origin --set-upstream main
  stderr: 'error: src refspec --set-upstream does not match any
error: failed to push some refs to 'git@github.com''
2025-09-27 23:30:42,324 - WARNING: 尝试 2/3 失败: Cmd('git') failed due to: exit code(1)
  cmdline: git push --porcelain -- origin --set-upstream main
  stderr: 'error: src refspec --set-upstream does not match any
error: failed to push some refs to 'git@github.com''
2025-09-27 23:30:46,565 - WARNING: 尝试 3/3 失败: Cmd('git') failed due to: exit code(1)
  cmdline: git push --porcelain -- origin --set-upstream main
  stderr: 'error: src refspec --set-upstream does not match any
error: failed to push some refs to 'git@github.com''
2025-09-27 23:30:46,565 - ERROR: 同步最终失败
2025-09-27 23:30:46,565 - ERROR: 错误详情
Traceback (most recent call last):
  File "C:\Users\10129\CodeBuddy\MutilTask\github_sync.py", line 82, in <module>
    syncer.sync()
    ~~~~~~~~~~~^^
  File "C:\Users\10129\CodeBuddy\MutilTask\github_sync.py", line 68, in sync
    repo.remotes.origin.push(push_args)
    ~~~~~~~~~~~~~~~~~~~~~~~~^^^^^^^^^^^
  File "C:\Python313\Lib\site-packages\git\remote.py", line 1210, in push
    return self._get_push_info(proc, progress, kill_after_timeout=kill_after_timeout)
           ~~~~~~~~~~~~~~~~~~~^^^^^^^^^^^^^^^^^^^^^^^^^^^^^^^^^^^^^^^^^^^^^^^^^^^^^^^
  File "C:\Python313\Lib\site-packages\git\remote.py", line 975, in _get_push_info
    proc.wait(stderr=stderr_text)
    ~~~~~~~~~^^^^^^^^^^^^^^^^^^^^
  File "C:\Python313\Lib\site-packages\git\cmd.py", line 419, in wait
    raise GitCommandError(remove_password_if_present(self.args), status, errstr)
git.exc.GitCommandError: Cmd('git') failed due to: exit code(1)
  cmdline: git push --porcelain -- origin --set-upstream main
  stderr: 'error: src refspec --set-upstream does not match any
error: failed to push some refs to 'git@github.com''
2025-09-27 23:32:24,753 - WARNING: 尝试 1/3 失败: Cmd('git') failed due to: exit code(128)
  cmdline: git push --set-upstream origin main
  stderr: 'fatal: 'git@github.com' does not appear to be a git repository
fatal: Could not read from remote repository.

Please make sure you have the correct access rights
and the repository exists.'
2025-09-27 23:32:27,017 - WARNING: 尝试 2/3 失败: Cmd('git') failed due to: exit code(128)
  cmdline: git push --set-upstream origin main
  stderr: 'fatal: 'git@github.com' does not appear to be a git repository
fatal: Could not read from remote repository.

Please make sure you have the correct access rights
and the repository exists.'
2025-09-27 23:32:31,289 - WARNING: 尝试 3/3 失败: Cmd('git') failed due to: exit code(128)
  cmdline: git push --set-upstream origin main
  stderr: 'fatal: 'git@github.com' does not appear to be a git repository
fatal: Could not read from remote repository.

Please make sure you have the correct access rights
and the repository exists.'
2025-09-27 23:32:31,289 - ERROR: 同步最终失败
2025-09-27 23:32:31,289 - ERROR: 错误详情
Traceback (most recent call last):
  File "C:\Users\10129\CodeBuddy\MutilTask\github_sync.py", line 87, in <module>
    syncer.sync()
    ~~~~~~~~~~~^^
  File "C:\Users\10129\CodeBuddy\MutilTask\github_sync.py", line 70, in sync
    repo.git.push('origin', branch_name, set_upstream=True)
    ~~~~~~~~~~~~~^^^^^^^^^^^^^^^^^^^^^^^^^^^^^^^^^^^^^^^^^^
  File "C:\Python313\Lib\site-packages\git\cmd.py", line 1003, in <lambda>
    return lambda *args, **kwargs: self._call_process(name, *args, **kwargs)
                                   ~~~~~~~~~~~~~~~~~~^^^^^^^^^^^^^^^^^^^^^^^
  File "C:\Python313\Lib\site-packages\git\cmd.py", line 1616, in _call_process
    return self.execute(call, **exec_kwargs)
           ~~~~~~~~~~~~^^^^^^^^^^^^^^^^^^^^^
  File "C:\Python313\Lib\site-packages\git\cmd.py", line 1406, in execute
    raise GitCommandError(redacted_command, status, stderr_value, stdout_value)
git.exc.GitCommandError: Cmd('git') failed due to: exit code(128)
  cmdline: git push --set-upstream origin main
  stderr: 'fatal: 'git@github.com' does not appear to be a git repository
fatal: Could not read from remote repository.

Please make sure you have the correct access rights
and the repository exists.'
2025-09-27 23:35:09,393 - INFO: Git仓库初始化成功
2025-09-27 23:35:09,393 - INFO: 配置的远程仓库URL: git@github.com:ssLinChen/lite-mutil-task-manager.git
2025-09-27 23:35:09,393 - INFO: 测试SSH连接到: github.com
2025-09-27 23:35:12,850 - INFO: SSH连接测试成功: github.com
2025-09-27 23:35:12,851 - INFO: 检查仓库是否存在: ssLinChen/lite-mutil-task-manager 在 github.com
2025-09-27 23:35:24,073 - WARNING: 检查仓库存在性异常: Command '['git', 'ls-remote', 'git@github.com:ssLinChen/lite-mutil-task-manager.git', 'HEAD']' timed out after 10 seconds
2025-09-27 23:35:24,073 - WARNING: 远程仓库不存在或无法访问
2025-09-27 23:35:24,073 - INFO: 请确认仓库URL是否正确，并且您有权限访问该仓库
2025-09-27 23:35:24,078 - INFO: Git身份设置为: tutu <y80200156@mail.ecust.edu.cn>
2025-09-27 23:35:24,128 - INFO: 已添加所有更改到暂存区
2025-09-27 23:35:24,239 - INFO: 已提交更改: Auto-commit at 2025-09-27 23:35:24
2025-09-27 23:35:24,240 - INFO: 更新远程仓库URL: git@github.com -> git@github.com:ssLinChen/lite-mutil-task-manager.git
2025-09-27 23:35:24,269 - INFO: 使用分支: main
2025-09-27 23:35:24,306 - INFO: 本地分支 main 已存在
2025-09-27 23:35:24,306 - INFO: 开始推送到远程仓库...
2025-09-27 23:35:24,306 - INFO: 使用 --set-upstream 选项推送分支 main
2025-09-27 23:35:29,660 - WARNING: 尝试 1/3 失败: Cmd('git') failed due to: exit code(1)
  cmdline: git push --set-upstream origin main
  stderr: 'To github.com:ssLinChen/lite-mutil-task-manager.git
 ! [rejected]        main -> main (fetch first)
error: failed to push some refs to 'github.com:ssLinChen/lite-mutil-task-manager.git'
hint: Updates were rejected because the remote contains work that you do not
hint: have locally. This is usually caused by another repository pushing to
hint: the same ref. If you want to integrate the remote changes, use
hint: 'git pull' before pushing again.
hint: See the 'Note about fast-forwards' in 'git push --help' for details.'
2025-09-27 23:35:29,660 - INFO: 等待 2 秒后重试...
2025-09-27 23:35:31,668 - INFO: Git身份设置为: tutu <y80200156@mail.ecust.edu.cn>
2025-09-27 23:35:31,719 - INFO: 已添加所有更改到暂存区
2025-09-27 23:35:31,786 - INFO: 已提交更改: Auto-commit at 2025-09-27 23:35:31
2025-09-27 23:35:31,787 - INFO: 远程仓库URL已正确设置: git@github.com:ssLinChen/lite-mutil-task-manager.git
2025-09-27 23:35:31,787 - INFO: 使用分支: main
2025-09-27 23:35:31,813 - INFO: 本地分支 main 已存在
2025-09-27 23:35:31,814 - INFO: 开始推送到远程仓库...
2025-09-27 23:35:31,814 - INFO: 使用 --set-upstream 选项推送分支 main
2025-09-27 23:35:35,530 - WARNING: 尝试 2/3 失败: Cmd('git') failed due to: exit code(1)
  cmdline: git push --set-upstream origin main
  stderr: 'To github.com:ssLinChen/lite-mutil-task-manager.git
 ! [rejected]        main -> main (fetch first)
error: failed to push some refs to 'github.com:ssLinChen/lite-mutil-task-manager.git'
hint: Updates were rejected because the remote contains work that you do not
hint: have locally. This is usually caused by another repository pushing to
hint: the same ref. If you want to integrate the remote changes, use
hint: 'git pull' before pushing again.
hint: See the 'Note about fast-forwards' in 'git push --help' for details.'
2025-09-27 23:35:35,530 - INFO: 等待 4 秒后重试...
2025-09-27 23:35:39,536 - INFO: Git身份设置为: tutu <y80200156@mail.ecust.edu.cn>
2025-09-27 23:35:39,587 - INFO: 已添加所有更改到暂存区
2025-09-27 23:35:39,660 - INFO: 已提交更改: Auto-commit at 2025-09-27 23:35:39
2025-09-27 23:35:39,660 - INFO: 远程仓库URL已正确设置: git@github.com:ssLinChen/lite-mutil-task-manager.git
2025-09-27 23:35:39,661 - INFO: 使用分支: main
2025-09-27 23:35:39,689 - INFO: 本地分支 main 已存在
2025-09-27 23:35:39,689 - INFO: 开始推送到远程仓库...
2025-09-27 23:35:39,690 - INFO: 使用 --set-upstream 选项推送分支 main
2025-09-27 23:35:43,479 - WARNING: 尝试 3/3 失败: Cmd('git') failed due to: exit code(1)
  cmdline: git push --set-upstream origin main
  stderr: 'To github.com:ssLinChen/lite-mutil-task-manager.git
 ! [rejected]        main -> main (fetch first)
error: failed to push some refs to 'github.com:ssLinChen/lite-mutil-task-manager.git'
hint: Updates were rejected because the remote contains work that you do not
hint: have locally. This is usually caused by another repository pushing to
hint: the same ref. If you want to integrate the remote changes, use
hint: 'git pull' before pushing again.
hint: See the 'Note about fast-forwards' in 'git push --help' for details.'
2025-09-27 23:35:43,479 - ERROR: 达到最大重试次数，同步最终失败
2025-09-27 23:35:43,480 - ERROR: 错误详情
Traceback (most recent call last):
  File "C:\Users\10129\CodeBuddy\MutilTask\github_sync.py", line 225, in <module>
    syncer.sync()
    ~~~~~~~~~~~^^
  File "C:\Users\10129\CodeBuddy\MutilTask\github_sync.py", line 191, in sync
    self.repo.git.push('origin', branch_name, set_upstream=True)
    ~~~~~~~~~~~~~~~~~~^^^^^^^^^^^^^^^^^^^^^^^^^^^^^^^^^^^^^^^^^^
  File "C:\Python313\Lib\site-packages\git\cmd.py", line 1003, in <lambda>
    return lambda *args, **kwargs: self._call_process(name, *args, **kwargs)
                                   ~~~~~~~~~~~~~~~~~~^^^^^^^^^^^^^^^^^^^^^^^
  File "C:\Python313\Lib\site-packages\git\cmd.py", line 1616, in _call_process
    return self.execute(call, **exec_kwargs)
           ~~~~~~~~~~~~^^^^^^^^^^^^^^^^^^^^^
  File "C:\Python313\Lib\site-packages\git\cmd.py", line 1406, in execute
    raise GitCommandError(redacted_command, status, stderr_value, stdout_value)
git.exc.GitCommandError: Cmd('git') failed due to: exit code(1)
  cmdline: git push --set-upstream origin main
  stderr: 'To github.com:ssLinChen/lite-mutil-task-manager.git
 ! [rejected]        main -> main (fetch first)
error: failed to push some refs to 'github.com:ssLinChen/lite-mutil-task-manager.git'
hint: Updates were rejected because the remote contains work that you do not
hint: have locally. This is usually caused by another repository pushing to
hint: the same ref. If you want to integrate the remote changes, use
hint: 'git pull' before pushing again.
hint: See the 'Note about fast-forwards' in 'git push --help' for details.'
