2025-09-27 23:28:55,579 - WARNING: ≥¢ ‘ 1/3  ß∞‹: Cmd('git') failed due to: exit code(1)
  cmdline: git push --porcelain -- origin --set-upstream main
  stderr: 'error: src refspec --set-upstream does not match any
error: failed to push some refs to 'git@github.com''
2025-09-27 23:28:57,813 - WARNING: ≥¢ ‘ 2/3  ß∞‹: Cmd('git') failed due to: exit code(1)
  cmdline: git push --porcelain -- origin --set-upstream main
  stderr: 'error: src refspec --set-upstream does not match any
error: failed to push some refs to 'git@github.com''
2025-09-27 23:29:37,716 - WARNING: ≥¢ ‘ 1/3  ß∞‹: Cmd('git') failed due to: exit code(1)
  cmdline: git push --porcelain -- origin --set-upstream main
  stderr: 'error: src refspec --set-upstream does not match any
error: failed to push some refs to 'git@github.com''
2025-09-27 23:29:39,973 - WARNING: ≥¢ ‘ 2/3  ß∞‹: Cmd('git') failed due to: exit code(1)
  cmdline: git push --porcelain -- origin --set-upstream main
  stderr: 'error: src refspec --set-upstream does not match any
error: failed to push some refs to 'git@github.com''
2025-09-27 23:30:25,334 - WARNING: ≥¢ ‘ 1/3  ß∞‹: Cmd('git') failed due to: exit code(1)
  cmdline: git push --porcelain -- origin --set-upstream main
  stderr: 'error: src refspec --set-upstream does not match any
error: failed to push some refs to 'git@github.com''
2025-09-27 23:30:27,574 - WARNING: ≥¢ ‘ 2/3  ß∞‹: Cmd('git') failed due to: exit code(1)
  cmdline: git push --porcelain -- origin --set-upstream main
  stderr: 'error: src refspec --set-upstream does not match any
error: failed to push some refs to 'git@github.com''
2025-09-27 23:30:31,816 - WARNING: ≥¢ ‘ 3/3  ß∞‹: Cmd('git') failed due to: exit code(1)
  cmdline: git push --porcelain -- origin --set-upstream main
  stderr: 'error: src refspec --set-upstream does not match any
error: failed to push some refs to 'git@github.com''
2025-09-27 23:30:31,816 - ERROR: Õ¨≤Ω◊Ó÷’ ß∞‹
2025-09-27 23:30:31,817 - ERROR: ¥ÌŒÛœÍ«È
Traceback (most recent call last):
  File "C:\Users\10129\CodeBuddy\MutilTask\github_sync.py", line 82, in <module>
    syncer.sync()
    ~~~~~~~~~~~^^
  File "C:\Users\10129\CodeBuddy\MutilTask\github_sync.py", line 68, in sync
    repo.remotes.origin.push(push_args)
    ~~~~~~~~~~~~~~~~~~~~~~~~^^^^^^^^^^^
  File "C:\Python313\Lib\site-packages\git\remote.py", line 1210, in push
    return self._get_push_info(proc, progress, kill_after_timeout=kill_after_timeout)
           ~~~~~~~~~~~~~~~~~~~^^^^^^^^^^^^^^^^^^^^^^^^^^^^^^^^^^^^^^^^^^^^^^^^^^^^^^^
  File "C:\Python313\Lib\site-packages\git\remote.py", line 975, in _get_push_info
    proc.wait(stderr=stderr_text)
    ~~~~~~~~~^^^^^^^^^^^^^^^^^^^^
  File "C:\Python313\Lib\site-packages\git\cmd.py", line 419, in wait
    raise GitCommandError(remove_password_if_present(self.args), status, errstr)
git.exc.GitCommandError: Cmd('git') failed due to: exit code(1)
  cmdline: git push --porcelain -- origin --set-upstream main
  stderr: 'error: src refspec --set-upstream does not match any
error: failed to push some refs to 'git@github.com''
2025-09-27 23:30:40,079 - WARNING: ≥¢ ‘ 1/3  ß∞‹: Cmd('git') failed due to: exit code(1)
  cmdline: git push --porcelain -- origin --set-upstream main
  stderr: 'error: src refspec --set-upstream does not match any
error: failed to push some refs to 'git@github.com''
2025-09-27 23:30:42,324 - WARNING: ≥¢ ‘ 2/3  ß∞‹: Cmd('git') failed due to: exit code(1)
  cmdline: git push --porcelain -- origin --set-upstream main
  stderr: 'error: src refspec --set-upstream does not match any
error: failed to push some refs to 'git@github.com''
2025-09-27 23:30:46,565 - WARNING: ≥¢ ‘ 3/3  ß∞‹: Cmd('git') failed due to: exit code(1)
  cmdline: git push --porcelain -- origin --set-upstream main
  stderr: 'error: src refspec --set-upstream does not match any
error: failed to push some refs to 'git@github.com''
2025-09-27 23:30:46,565 - ERROR: Õ¨≤Ω◊Ó÷’ ß∞‹
2025-09-27 23:30:46,565 - ERROR: ¥ÌŒÛœÍ«È
Traceback (most recent call last):
  File "C:\Users\10129\CodeBuddy\MutilTask\github_sync.py", line 82, in <module>
    syncer.sync()
    ~~~~~~~~~~~^^
  File "C:\Users\10129\CodeBuddy\MutilTask\github_sync.py", line 68, in sync
    repo.remotes.origin.push(push_args)
    ~~~~~~~~~~~~~~~~~~~~~~~~^^^^^^^^^^^
  File "C:\Python313\Lib\site-packages\git\remote.py", line 1210, in push
    return self._get_push_info(proc, progress, kill_after_timeout=kill_after_timeout)
           ~~~~~~~~~~~~~~~~~~~^^^^^^^^^^^^^^^^^^^^^^^^^^^^^^^^^^^^^^^^^^^^^^^^^^^^^^^
  File "C:\Python313\Lib\site-packages\git\remote.py", line 975, in _get_push_info
    proc.wait(stderr=stderr_text)
    ~~~~~~~~~^^^^^^^^^^^^^^^^^^^^
  File "C:\Python313\Lib\site-packages\git\cmd.py", line 419, in wait
    raise GitCommandError(remove_password_if_present(self.args), status, errstr)
git.exc.GitCommandError: Cmd('git') failed due to: exit code(1)
  cmdline: git push --porcelain -- origin --set-upstream main
  stderr: 'error: src refspec --set-upstream does not match any
error: failed to push some refs to 'git@github.com''
2025-09-27 23:32:24,753 - WARNING: ≥¢ ‘ 1/3  ß∞‹: Cmd('git') failed due to: exit code(128)
  cmdline: git push --set-upstream origin main
  stderr: 'fatal: 'git@github.com' does not appear to be a git repository
fatal: Could not read from remote repository.

Please make sure you have the correct access rights
and the repository exists.'
2025-09-27 23:32:27,017 - WARNING: ≥¢ ‘ 2/3  ß∞‹: Cmd('git') failed due to: exit code(128)
  cmdline: git push --set-upstream origin main
  stderr: 'fatal: 'git@github.com' does not appear to be a git repository
fatal: Could not read from remote repository.

Please make sure you have the correct access rights
and the repository exists.'
2025-09-27 23:32:31,289 - WARNING: ≥¢ ‘ 3/3  ß∞‹: Cmd('git') failed due to: exit code(128)
  cmdline: git push --set-upstream origin main
  stderr: 'fatal: 'git@github.com' does not appear to be a git repository
fatal: Could not read from remote repository.

Please make sure you have the correct access rights
and the repository exists.'
2025-09-27 23:32:31,289 - ERROR: Õ¨≤Ω◊Ó÷’ ß∞‹
2025-09-27 23:32:31,289 - ERROR: ¥ÌŒÛœÍ«È
Traceback (most recent call last):
  File "C:\Users\10129\CodeBuddy\MutilTask\github_sync.py", line 87, in <module>
    syncer.sync()
    ~~~~~~~~~~~^^
  File "C:\Users\10129\CodeBuddy\MutilTask\github_sync.py", line 70, in sync
    repo.git.push('origin', branch_name, set_upstream=True)
    ~~~~~~~~~~~~~^^^^^^^^^^^^^^^^^^^^^^^^^^^^^^^^^^^^^^^^^^
  File "C:\Python313\Lib\site-packages\git\cmd.py", line 1003, in <lambda>
    return lambda *args, **kwargs: self._call_process(name, *args, **kwargs)
                                   ~~~~~~~~~~~~~~~~~~^^^^^^^^^^^^^^^^^^^^^^^
  File "C:\Python313\Lib\site-packages\git\cmd.py", line 1616, in _call_process
    return self.execute(call, **exec_kwargs)
           ~~~~~~~~~~~~^^^^^^^^^^^^^^^^^^^^^
  File "C:\Python313\Lib\site-packages\git\cmd.py", line 1406, in execute
    raise GitCommandError(redacted_command, status, stderr_value, stdout_value)
git.exc.GitCommandError: Cmd('git') failed due to: exit code(128)
  cmdline: git push --set-upstream origin main
  stderr: 'fatal: 'git@github.com' does not appear to be a git repository
fatal: Could not read from remote repository.

Please make sure you have the correct access rights
and the repository exists.'
